Workbook
Name _Order1: 0
Name A: BlankMacro1
Name A: BlankMacro1
Name A: BlankMacro1
Name AAAA: BlankMacro1
Name AAAA: BlankMacro1
Name AAAA: BlankMacro1
Name HTML1_1: "'[클레임.xls]클레임 기안'!$A$2:$I$34"
Name HTML1_10: ""
Name HTML1_11: 1
Name HTML1_12: "C:\My Documents\MyHTML.htm"
Name HTML1_2: 1
Name HTML1_3: "클레임.xl"
Name HTML1_4: "클레임 기안"
Name HTML1_5: "연습용입니다."
Name HTML1_6: 1
Name HTML1_7: -4146
Name HTML1_8: "97-02-26"
Name HTML1_9: "전광호"
Name HTMLCount: 1
Name ID: [1]ITEM!$F$4:$F$587
Name LINE: [1]ITEM!$C$4:$C$587
Name RODLS: BlankMacro1
Name RODLS: BlankMacro1
Name RODLS: BlankMacro1
Name S: BlankMacro1
Name S: BlankMacro1
Name S: BlankMacro1
Name SAPBEXhrIndnt: "Wide"
Name SAPsysID: "708C5W7SBKP804JT78WJ0JNKI"
Name SAPwbID: "ARS"
Name sdkljfkljasdf: [2]SM!$L$11:$L$84
Name SKU: '[3]15SS MDPLAN 취합'!$Y:$Y
Name ST수: '[3]15SS MDPLAN 취합'!$X:$X
Name 가격: [4]원가!$A$1:$C$65536
Name 개인: BlankMacro1
Name 개인: BlankMacro1
Name 개인: BlankMacro1
Name 개인별분배: BlankMacro1
Name 개인별분배: BlankMacro1
Name 개인별분배: BlankMacro1
Name 개인별분배1: BlankMacro1
Name 개인별분배1: BlankMacro1
Name 개인별분배1: BlankMacro1
Name 거래처: '[5]2004'!$C:$C
Name 거래처1: '[5]2005'!$C:$C
Name 겨율: BlankMacro1
Name 겨율: BlankMacro1
Name 겨율: BlankMacro1
Name 공급금액: [6]ITEM!$AE$6:$AE$364
Name 구월사주: OFFSET([7]주간분석!$C$29,0,0,COUNTA([7]주간분석!$C$1:$C$65536)-1)
Name 금호기타불량: '[8]금호 산업'!$AT$13
Name 금호기획: '[8]금호 산업'!$K$13
Name 금호기획량: '[8]금호 산업'!$B$13
Name 금호요척량: '[8]금호 산업'!$AA$13
Name 금호원불: '[8]금호 산업'!$AR$13
Name 금호정품입고: '[8]금호 산업'!$AP$13
Name 금호취불: '[8]금호 산업'!$AS$13
Name 기여도: BlankMacro1
Name 기여도: BlankMacro1

Sheet 동향 그래프 ~시세반영 
A1: DOWN(충전재) 시세 | Y1: 75.5 | Z1: 126.9 | AA1: =(Y1-Z1)/Y1 -> -0.6807947 | AB1: 77.2 | AC1: 131.2 | AD1: =(AB1-AC1)/AB1 -> -0.69948187 | CF1: 12월평균 | CG1: =AVERAGE(CF13:CG13) -> 86.1725
O2: 23년 | AL2: 24년
A3: 업체명 | B3: 44747 | C3: 44761 | D3: 44783 | E3: 44797 | F3: 44811 | G3: 45191 | H3: 45204 | I3: 45221 | J3: 45232 | K3: 45246 | L3: 45260 | M3: 45273 | N3: 45287 | O3: 44944 | P3: 44957 | Q3: 44966 | R3: 44980 | S3: 44994 | T3: 45015 | U3: 45033 | V3: 45050 | W3: 45064 | X3: 45078 | Y3: 45092 | Z3: 45106 | AA3: 45120 | AB3: 45134 | AC3: 45155 | AD3: 45169 | AE3: 45183 | AF3: 45203 | AG3: 45225 | AH3: 45239 | AI3: 45257 | AJ3: 45640 | AK3: 45654 | AL3: 45301 | AM3: 45316 | AN3: 45329 | AO3: 45343 | AP3: 45357 | AQ3: 45369 | AR3: 45385 | AS3: 45399 | AT3: 45421 | AU3: 45434 | AV3: 45448 | AW3: 45462 | AX3: 45476 | AY3: 45498 | AZ3: 45511 | BA3: 45526 | BB3: 45541 | BC3: 45562 | BD3: 45580 | BE3: 45593 | BF3: 45611 | BG3: 45623 | BH3: 45639 | BI3: 45653 | BJ3: 45666 | BK3: 45701 | BL3: 45716 | BM3: 45729 | BN3: 45757 | BO3: 45764 | BP3: 45778 | BQ3: 45793 | BR3: 45806 | BS3: 45820 | BT3: 45833 | BU3: 45848 | BV3: 45862 | BW3: 45876 | BX3: 45890 | BY3: 45904 | BZ3: 45917 | CA3: 45932 | CB3: 45946 | CC3: 45959 | CD3: 45975 | CE3: 45988 | CF3: 46002 | CG3: 46020 | CH3: 46031 | CI3: 46051 | CJ3: 46057 | CK3: 46073 | CL3: 46093 | CM3: 46114 | CN3: 46132 | CO3: 46142 | CP3: 46163 | CQ3: 46192 | CR3: 46212 | CS3: 46233 | CT3: 46247 | CU3: 46269
A4: PCK | B4: 73 | C4: 73 | D4: 74.5 | E4: 74.5 | F4: 76.5 | G4: 76.5 | H4: 84.5 | I4: 84.5 | J4: 84.5 | K4: 80 | L4: 74.5 | M4: 74.5 | N4: 74 | O4: 74 | P4: 74 | Q4: 69.5 | R4: 70.5 | S4: 71 | T4: 70.5 | U4: 70.5 | V4: 76 | W4: 76 | X4: 76 | Y4: 76 | Z4: 78 | AA4: 78 | AB4: 78 | AC4: 78.5 | AD4: 79 | AE4: 77 | AF4: 77 | AG4: 78 | AH4: 78 | AI4: 81 | AJ4: 83 | AK4: 83 | AL4: 82 | AM4: 84 | AN4: 88 | AO4: 95 | AP4: 100 | AQ4: 102 | AR4: 97 | AS4: 97 | AT4: 97 | AU4: 102 | AV4: 110 | AW4: 113 | AX4: 115 | AY4: 115 | AZ4: 115 | BA4: 115 | BB4: 115 | BC4: 117 | BD4: 117 | BE4: 116 | BF4: 114 | BG4: 108 | BH4: 98 | BI4: 98 | BJ4: 98 | BK4: 98 | BL4: 95 | BM4: 94 | BN4: 92 | BO4: 92 | BP4: 92 | BQ4: 91 | BR4: {=INDEX('DOWN 가격동향'!$DD$10:$AHC$10,MATCH(1,('DOWN 가격동향'!$K$8:$AHC$8='동향 그래프 ~시세반영 '!$A4)*('DOWN 가격동향'!$DD$9:$AHC$9='동향 그래프 ~시세반영 '!BR$3),0))} -> 91 | BS4: {=INDEX('DOWN 가격동향'!$DD$10:$AHC$10,MATCH(1,('DOWN 가격동향'!$K$8:$AHC$8='동향 그래프 ~시세반영 '!$A4)*('DOWN 가격동향'!$DD$9:$AHC$9='동향 그래프 ~시세반영 '!BS$3),0))} -> 92 | BT4: {=INDEX('DOWN 가격동향'!$DD$10:$AHC$10,MATCH(1,('DOWN 가격동향'!$K$8:$AHC$8='동향 그래프 ~시세반영 '!$A4)*('DOWN 가격동향'!$DD$9:$AHC$9='동향 그래프 ~시세반영 '!BT$3),0))} -> 92 | BU4: {=INDEX('DOWN 가격동향'!$DD$10:$AHC$10,MATCH(1,('DOWN 가격동향'!$K$8:$AHC$8='동향 그래프 ~시세반영 '!$A4)*('DOWN 가격동향'!$DD$9:$AHC$9='동향 그래프 ~시세반영 '!BU$3),0))} -> 91 | BV4: {=INDEX('DOWN 가격동향'!$DD$10:$AHC$10,MATCH(1,('DOWN 가격동향'!$K$8:$AHC$8='동향 그래프 ~시세반영 '!$A4)*('DOWN 가격동향'!$DD$9:$AHC$9='동향 그래프 ~시세반영 '!BV$3),0))} -> 87 | BW4: {=INDEX('DOWN 가격동향'!$DD$10:$AHC$10,MATCH(1,('DOWN 가격동향'!$K$8:$AHC$8='동향 그래프 ~시세반영 '!$A4)*('DOWN 가격동향'!$DD$9:$AHC$9='동향 그래프 ~시세반영 '!BW$3),0))} -> 87 | BX4: {=INDEX('DOWN 가격동향'!$DD$10:$AHC$10,MATCH(1,('DOWN 가격동향'!$K$8:$AHC$8='동향 그래프 ~시세반영 '!$A4)*('DOWN 가격동향'!$DD$9:$AHC$9='동향 그래프 ~시세반영 '!BX$3),0))} -> 87 | BY4: {=INDEX('DOWN 가격동향'!$DD$10:$AHC$10,MATCH(1,('DOWN 가격동향'!$K$8:$AHC$8='동향 그래프 ~시세반영 '!$A4)*('DOWN 가격동향'!$DD$9:$AHC$9='동향 그래프 ~시세반영 '!BY$3),0))} -> 87 | ... CT4: {=INDEX('DOWN 가격동향'!$DD$10:$AHC$10,MATCH(1,('DOWN 가격동향'!$K$8:$AHC$8='동향 그래프 ~시세반영 '!$A4)*('DOWN 가격동향'!$DD$9:$AHC$9='동향 그래프 ~시세반영 '!CT$3),0))} -> 95 | CU4: {=INDEX('DOWN 가격동향'!$DD$10:$BBC$10,MATCH(1,('DOWN 가격동향'!$K$8:$BBC$8='동향 그래프 ~시세반영 '!A4)*('DOWN 가격동향'!$DD$9:$BBC$9='동향 그래프 ~시세반영 '!CU$3),0))} -> 95
A5: 광륭 | B5: 71.5 | C5: 73.5 | D5: 75.5 | E5: 79.5 | F5: 75.5 | G5: 72.5 | H5: 75 | I5: 74.5 | J5: 73 | K5: 72 | L5: 71.5 | M5: 71 | N5: 73.5 | O5: 73.5 | P5: 73.5 | Q5: 70 | R5: 85 | S5: 88 | T5: 91.5 | U5: 90 | V5: 94 | W5: 94 | X5: 93.5 | Y5: 82.5 | Z5: 82.5 | AA5: 82.8 | AB5: 83 | AC5: 82.8 | AD5: 83.3 | AE5: 83.3 | AF5: 90 | AG5: 74 | AH5: 74 | AI5: 75 | AJ5: 83.5 | AK5: 82 | AL5: 83 | AM5: 90 | AN5: 99.5 | AO5: 103 | AP5: 107 | AQ5: 105 | AR5: 104 | AS5: 104 | AT5: 105 | AU5: 107 | AV5: 120 | AW5: 125 | AX5: 123 | AY5: 123 | AZ5: 122 | BA5: 119 | BB5: 119 | BC5: 115 | BD5: 115 | BE5: 115 | BF5: 114 | BG5: 102.5 | BH5: 98 | BI5: 103.5 | BJ5: 103.5 | BK5: 102 | BL5: 93 | BM5: 95 | BN5: 91 | BO5: 91 | BP5: 89 | BQ5: 82 | BR5: {=INDEX('DOWN 가격동향'!$DD$10:$AHC$10,MATCH(1,('DOWN 가격동향'!$K$8:$AHC$8='동향 그래프 ~시세반영 '!$A5)*('DOWN 가격동향'!$DD$9:$AHC$9='동향 그래프 ~시세반영 '!BR$3),0))} -> 82 | BS5: {=INDEX('DOWN 가격동향'!$DD$10:$AHC$10,MATCH(1,('DOWN 가격동향'!$K$8:$AHC$8='동향 그래프 ~시세반영 '!$A5)*('DOWN 가격동향'!$DD$9:$AHC$9='동향 그래프 ~시세반영 '!BS$3),0))} -> 85 | BT5: {=INDEX('DOWN 가격동향'!$DD$10:$AHC$10,MATCH(1,('DOWN 가격동향'!$K$8:$AHC$8='동향 그래프 ~시세반영 '!$A5)*('DOWN 가격동향'!$DD$9:$AHC$9='동향 그래프 ~시세반영 '!BT$3),0))} -> 86.6 | BU5: {=INDEX('DOWN 가격동향'!$DD$10:$AHC$10,MATCH(1,('DOWN 가격동향'!$K$8:$AHC$8='동향 그래프 ~시세반영 '!$A5)*('DOWN 가격동향'!$DD$9:$AHC$9='동향 그래프 ~시세반영 '!BU$3),0))} -> 84.6 | BV5: {=INDEX('DOWN 가격동향'!$DD$10:$AHC$10,MATCH(1,('DOWN 가격동향'!$K$8:$AHC$8='동향 그래프 ~시세반영 '!$A5)*('DOWN 가격동향'!$DD$9:$AHC$9='동향 그래프 ~시세반영 '!BV$3),0))} -> 84 | BW5: {=INDEX('DOWN 가격동향'!$DD$10:$AHC$10,MATCH(1,('DOWN 가격동향'!$K$8:$AHC$8='동향 그래프 ~시세반영 '!$A5)*('DOWN 가격동향'!$DD$9:$AHC$9='동향 그래프 ~시세반영 '!BW$3),0))} -> 84 | BX5: {=INDEX('DOWN 가격동향'!$DD$10:$AHC$10,MATCH(1,('DOWN 가격동향'!$K$8:$AHC$8='동향 그래프 ~시세반영 '!$A5)*('DOWN 가격동향'!$DD$9:$AHC$9='동향 그래프 ~시세반영 '!BX$3),0))} -> 84 | BY5: {=INDEX('DOWN 가격동향'!$DD$10:$AHC$10,MATCH(1,('DOWN 가격동향'!$K$8:$AHC$8='동향 그래프 ~시세반영 '!$A5)*('DOWN 가격동향'!$DD$9:$AHC$9='동향 그래프 ~시세반영 '!BY$3),0))} -> 85 | ... CT5: {=INDEX('DOWN 가격동향'!$DD$10:$AHC$10,MATCH(1,('DOWN 가격동향'!$K$8:$AHC$8='동향 그래프 ~시세반영 '!$A5)*('DOWN 가격동향'!$DD$9:$AHC$9='동향 그래프 ~시세반영 '!CT$3),0))} -> 107 | CU5: {=INDEX('DOWN 가격동향'!$DD$10:$BBC$10,MATCH(1,('DOWN 가격동향'!$K$8:$BBC$8='동향 그래프 ~시세반영 '!A5)*('DOWN 가격동향'!$DD$9:$BBC$9='동향 그래프 ~시세반영 '!CU$3),0))} -> 110
A6: 다음앤큐큐 | B6: 66.3 | C6: 66.3 | D6: 66.3 | E6: 66.3 | F6: 72.3 | G6: 72.3 | H6: 71 | I6: 71 | J6: 69 | K6: 69 | L6: 69 | M6: 67 | N6: 67 | O6: 67 | P6: 67 | Q6: 75.3 | R6: 75.3 | S6: 71.3 | T6: 75.3 | U6: 75.3 | V6: 72.3 | W6: 72.3 | X6: 72.3 | Y6: 72.3 | Z6: 72.3 | AA6: 72.3 | AB6: 72.3 | AC6: 72.3 | AD6: 72.3 | AE6: 72.3 | AF6: 73 | AG6: 72 | AH6: 73 | AI6: 76 | AJ6: 79 | AK6: 79 | AL6: 78 | AM6: 90 | AN6: 100 | AO6: 105 | AP6: 105 | AQ6: 105 | AR6: 110 | AS6: 110 | AT6: 105 | AU6: 115 | AV6: 128 | AW6: 128 | AX6: 132 | AY6: 132 | AZ6: 118 | BA6: 114 | BB6: 114 | BC6: 114 | BD6: 113 | BE6: 108 | BF6: 103 | BG6: 99 | BH6: 87.3 | BI6: 89.3 | BJ6: 86.3 | BK6: 86.3 | BL6: 86.3 | BM6: 86.3 | BN6: 85 | BO6: 80.3 | BP6: 79.3 | BQ6: 82.8 | BR6: {=INDEX('DOWN 가격동향'!$DD$10:$AHC$10,MATCH(1,('DOWN 가격동향'!$K$8:$AHC$8='동향 그래프 ~시세반영 '!$A6)*('DOWN 가격동향'!$DD$9:$AHC$9='동향 그래프 ~시세반영 '!BR$3),0))} -> 86.3 | BS6: {=INDEX('DOWN 가격동향'!$DD$10:$AHC$10,MATCH(1,('DOWN 가격동향'!$K$8:$AHC$8='동향 그래프 ~시세반영 '!$A6)*('DOWN 가격동향'!$DD$9:$AHC$9='동향 그래프 ~시세반영 '!BS$3),0))} -> 84.3 | BT6: {=INDEX('DOWN 가격동향'!$DD$10:$AHC$10,MATCH(1,('DOWN 가격동향'!$K$8:$AHC$8='동향 그래프 ~시세반영 '!$A6)*('DOWN 가격동향'!$DD$9:$AHC$9='동향 그래프 ~시세반영 '!BT$3),0))} -> 84.3 | BU6: {=INDEX('DOWN 가격동향'!$DD$10:$AHC$10,MATCH(1,('DOWN 가격동향'!$K$8:$AHC$8='동향 그래프 ~시세반영 '!$A6)*('DOWN 가격동향'!$DD$9:$AHC$9='동향 그래프 ~시세반영 '!BU$3),0))} -> 81.3 | BV6: {=INDEX('DOWN 가격동향'!$DD$10:$AHC$10,MATCH(1,('DOWN 가격동향'!$K$8:$AHC$8='동향 그래프 ~시세반영 '!$A6)*('DOWN 가격동향'!$DD$9:$AHC$9='동향 그래프 ~시세반영 '!BV$3),0))} -> 81.3 | BW6: {=INDEX('DOWN 가격동향'!$DD$10:$AHC$10,MATCH(1,('DOWN 가격동향'!$K$8:$AHC$8='동향 그래프 ~시세반영 '!$A6)*('DOWN 가격동향'!$DD$9:$AHC$9='동향 그래프 ~시세반영 '!BW$3),0))} -> 81.3 | BX6: {=INDEX('DOWN 가격동향'!$DD$10:$AHC$10,MATCH(1,('DOWN 가격동향'!$K$8:$AHC$8='동향 그래프 ~시세반영 '!$A6)*('DOWN 가격동향'!$DD$9:$AHC$9='동향 그래프 ~시세반영 '!BX$3),0))} -> 81.3 | BY6: {=INDEX('DOWN 가격동향'!$DD$10:$AHC$10,MATCH(1,('DOWN 가격동향'!$K$8:$AHC$8='동향 그래프 ~시세반영 '!$A6)*('DOWN 가격동향'!$DD$9:$AHC$9='동향 그래프 ~시세반영 '!BY$3),0))} -> 81.3 | ... CT6: {=INDEX('DOWN 가격동향'!$DD$10:$AHC$10,MATCH(1,('DOWN 가격동향'!$K$8:$AHC$8='동향 그래프 ~시세반영 '!$A6)*('DOWN 가격동향'!$DD$9:$AHC$9='동향 그래프 ~시세반영 '!CT$3),0))} -> 0 | CU6: {=INDEX('DOWN 가격동향'!$DD$10:$BBC$10,MATCH(1,('DOWN 가격동향'!$K$8:$BBC$8='동향 그래프 ~시세반영 '!A6)*('DOWN 가격동향'!$DD$9:$BBC$9='동향 그래프 ~시세반영 '!CU$3),0))} -> 0
A7: ALLIED | B7: 68.4 | C7: 72 | D7: 72 | E7: 76.5 | F7: 74.5 | G7: 74.46 | H7: 71.65 | I7: 71.65 | J7: 71.65 | K7: 71.65 | L7: 71.07 | M7: 71.07 | N7: 69.12 | O7: 69.12 | P7: 69.12 | Q7: 77.2 | R7: 82.7 | S7: 82.7 | T7: 79.8 | U7: 79.8 | V7: 79.8 | W7: 79.3 | X7: 78.3 | Y7: 77.8 | Z7: 77.8 | AA7: 77.4 | AB7: 77.4 | AC7: 79.3 | AD7: 79.3 | AE7: 78.8 | AF7: 78.8 | AG7: 75.9 | AH7: 76.2 | AI7: 81.3 | AJ7: 97.2 | AK7: 97.2 | AL7: 104.6 | AM7: 109.1 | AN7: 109.1 | AO7: 112.1 | AP7: 112.1 | AQ7: 118.6 | AR7: 125.5 | AS7: 125.5 | AT7: 129.7 | AU7: 129.7 | AV7: 138.1 | AW7: 138.1 | AX7: 138.1 | AY7: 138.1 | AZ7: 138.9 | BA7: 138.9 | BB7: 138.1 | BC7: 124.1 | BD7: 124.1 | BE7: 125.7 | BF7: 102.4 | BG7: 99 | BH7: 92.1 | BI7: 92.1 | BJ7: 86.3 | BK7: 88.4 | BL7: 85.1 | BM7: 85.1 | BN7: 81.9 | BO7: 80.2 | BP7: 80.2 | BQ7: 77 | BR7: {=INDEX('DOWN 가격동향'!$DD$10:$AHC$10,MATCH(1,('DOWN 가격동향'!$K$8:$AHC$8='동향 그래프 ~시세반영 '!$A7)*('DOWN 가격동향'!$DD$9:$AHC$9='동향 그래프 ~시세반영 '!BR$3),0))} -> 79.1 | BS7: {=INDEX('DOWN 가격동향'!$DD$10:$AHC$10,MATCH(1,('DOWN 가격동향'!$K$8:$AHC$8='동향 그래프 ~시세반영 '!$A7)*('DOWN 가격동향'!$DD$9:$AHC$9='동향 그래프 ~시세반영 '!BS$3),0))} -> 79.1 | BT7: {=INDEX('DOWN 가격동향'!$DD$10:$AHC$10,MATCH(1,('DOWN 가격동향'!$K$8:$AHC$8='동향 그래프 ~시세반영 '!$A7)*('DOWN 가격동향'!$DD$9:$AHC$9='동향 그래프 ~시세반영 '!BT$3),0))} -> 79.1 | BU7: {=INDEX('DOWN 가격동향'!$DD$10:$AHC$10,MATCH(1,('DOWN 가격동향'!$K$8:$AHC$8='동향 그래프 ~시세반영 '!$A7)*('DOWN 가격동향'!$DD$9:$AHC$9='동향 그래프 ~시세반영 '!BU$3),0))} -> 76.3 | BV7: {=INDEX('DOWN 가격동향'!$DD$10:$AHC$10,MATCH(1,('DOWN 가격동향'!$K$8:$AHC$8='동향 그래프 ~시세반영 '!$A7)*('DOWN 가격동향'!$DD$9:$AHC$9='동향 그래프 ~시세반영 '!BV$3),0))} -> 75.8 | BW7: {=INDEX('DOWN 가격동향'!$DD$10:$AHC$10,MATCH(1,('DOWN 가격동향'!$K$8:$AHC$8='동향 그래프 ~시세반영 '!$A7)*('DOWN 가격동향'!$DD$9:$AHC$9='동향 그래프 ~시세반영 '!BW$3),0))} -> 75.8 | BX7: {=INDEX('DOWN 가격동향'!$DD$10:$AHC$10,MATCH(1,('DOWN 가격동향'!$K$8:$AHC$8='동향 그래프 ~시세반영 '!$A7)*('DOWN 가격동향'!$DD$9:$AHC$9='동향 그래프 ~시세반영 '!BX$3),0))} -> 78.3 | BY7: {=INDEX('DOWN 가격동향'!$DD$10:$AHC$10,MATCH(1,('DOWN 가격동향'!$K$8:$AHC$8='동향 그래프 ~시세반영 '!$A7)*('DOWN 가격동향'!$DD$9:$AHC$9='동향 그래프 ~시세반영 '!BY$3),0))} -> 85.7 | ... CT7: {=INDEX('DOWN 가격동향'!$DD$10:$AHC$10,MATCH(1,('DOWN 가격동향'!$K$8:$AHC$8='동향 그래프 ~시세반영 '!$A7)*('DOWN 가격동향'!$DD$9:$AHC$9='동향 그래프 ~시세반영 '!CT$3),0))} -> 110.8 | CU7: {=INDEX('DOWN 가격동향'!$DD$10:$BBC$10,MATCH(1,('DOWN 가격동향'!$K$8:$BBC$8='동향 그래프 ~시세반영 '!A7)*('DOWN 가격동향'!$DD$9:$BBC$9='동향 그래프 ~시세반영 '!CU$3),0))} -> 110.2
A8: 태평양 | B8: 66.4 | C8: 66.2 | D8: 66.2 | E8: 67.3 | F8: 67.3 | G8: 67.3 | H8: 67 | I8: 66 | J8: 66 | K8: 66 | L8: 66 | M8: 66 | N8: 66 | O8: 66 | P8: 72 | Q8: 68 | R8: 69 | S8: 72 | T8: 68.3 | U8: 68.3 | V8: 68.3 | W8: 68.3 | X8: 68.3 | Y8: 68.3 | Z8: 76.6 | AA8: 76.6 | AB8: 76.6 | AC8: 76.6 | AD8: 76.6 | AE8: 76.6 | AF8: 76.6 | AG8: 78.7 | AH8: 78.7 | AI8: 78.7 | AJ8: 80.8 | AK8: 80.8 | AL8: 80.8 | AM8: 88.9 | AN8: 95 | AO8: 95 | AP8: 100 | AQ8: 100 | AR8: 103 | AS8: 103 | AT8: 106 | AU8: 115 | AV8: 123 | AW8: 123 | AX8: 145 | AY8: 145 | AZ8: 145 | BA8: 145 | BB8: 145 | BC8: 145 | BD8: 117.3 | BE8: 117.3 | BF8: 110.3 | BG8: 103 | BH8: 103 | BI8: 103 | BJ8: 103 | BK8: 90.3 | BL8: 86.8 | BM8: 86.3 | BN8: 81.3 | BO8: 82.3 | BP8: 83.3 | BQ8: 83.3 | BR8: {=INDEX('DOWN 가격동향'!$DD$10:$AHC$10,MATCH(1,('DOWN 가격동향'!$K$8:$AHC$8='동향 그래프 ~시세반영 '!$A8)*('DOWN 가격동향'!$DD$9:$AHC$9='동향 그래프 ~시세반영 '!BR$3),0))} -> 94.3 | BS8: {=INDEX('DOWN 가격동향'!$DD$10:$AHC$10,MATCH(1,('DOWN 가격동향'!$K$8:$AHC$8='동향 그래프 ~시세반영 '!$A8)*('DOWN 가격동향'!$DD$9:$AHC$9='동향 그래프 ~시세반영 '!BS$3),0))} -> 94.3 | BT8: {=INDEX('DOWN 가격동향'!$DD$10:$AHC$10,MATCH(1,('DOWN 가격동향'!$K$8:$AHC$8='동향 그래프 ~시세반영 '!$A8)*('DOWN 가격동향'!$DD$9:$AHC$9='동향 그래프 ~시세반영 '!BT$3),0))} -> 89.3 | BU8: {=INDEX('DOWN 가격동향'!$DD$10:$AHC$10,MATCH(1,('DOWN 가격동향'!$K$8:$AHC$8='동향 그래프 ~시세반영 '!$A8)*('DOWN 가격동향'!$DD$9:$AHC$9='동향 그래프 ~시세반영 '!BU$3),0))} -> 89.3 | BV8: {=INDEX('DOWN 가격동향'!$DD$10:$AHC$10,MATCH(1,('DOWN 가격동향'!$K$8:$AHC$8='동향 그래프 ~시세반영 '!$A8)*('DOWN 가격동향'!$DD$9:$AHC$9='동향 그래프 ~시세반영 '!BV$3),0))} -> 78.3 | BW8: {=INDEX('DOWN 가격동향'!$DD$10:$AHC$10,MATCH(1,('DOWN 가격동향'!$K$8:$AHC$8='동향 그래프 ~시세반영 '!$A8)*('DOWN 가격동향'!$DD$9:$AHC$9='동향 그래프 ~시세반영 '!BW$3),0))} -> 78.3 | BX8: {=INDEX('DOWN 가격동향'!$DD$10:$AHC$10,MATCH(1,('DOWN 가격동향'!$K$8:$AHC$8='동향 그래프 ~시세반영 '!$A8)*('DOWN 가격동향'!$DD$9:$AHC$9='동향 그래프 ~시세반영 '!BX$3),0))} -> 85.3 | BY8: {=INDEX('DOWN 가격동향'!$DD$10:$AHC$10,MATCH(1,('DOWN 가격동향'!$K$8:$AHC$8='동향 그래프 ~시세반영 '!$A8)*('DOWN 가격동향'!$DD$9:$AHC$9='동향 그래프 ~시세반영 '!BY$3),0))} -> 85.3 | ... CT8: {=INDEX('DOWN 가격동향'!$DD$10:$AHC$10,MATCH(1,('DOWN 가격동향'!$K$8:$AHC$8='동향 그래프 ~시세반영 '!$A8)*('DOWN 가격동향'!$DD$9:$AHC$9='동향 그래프 ~시세반영 '!CT$3),0))} -> 103.5 | CU8: {=INDEX('DOWN 가격동향'!$DD$10:$BBC$10,MATCH(1,('DOWN 가격동향'!$K$8:$BBC$8='동향 그래프 ~시세반영 '!A8)*('DOWN 가격동향'!$DD$9:$BBC$9='동향 그래프 ~시세반영 '!CU$3),0))} -> 111
A9: 신주원 | B9: 67.3 | C9: 67.8 | D9: 67.8 | E9: 68.3 | F9: 69.3 | G9: 69.3 | H9: 70 | I9: 70 | J9: 68 | K9: 68 | L9: 68 | M9: 70.3 | N9: 71 | O9: 72 | P9: 72 | Q9: 65.3 | R9: 66.3 | S9: 68.3 | T9: 71.3 | U9: 71.3 | V9: 74 | W9: 74 | X9: 76 | Y9: 76 | Z9: 76 | AA9: 76 | AB9: 76 | AC9: 76.3 | AD9: 76.3 | AE9: 76.3 | AF9: 76.3 | AG9: 76.3 | AH9: 76.3 | AI9: 72.3 | AJ9: 74.3 | AK9: 82.3 | AL9: 87.3 | AM9: 89.3 | AN9: 110.3 | AO9: 120.3 | AP9: 120.3 | AQ9: 120.3 | AR9: 120.3 | AS9: 120.3 | AT9: 120.3 | AU9: 120.3 | AV9: 132 | AW9: 134 | AX9: 134 | AY9: 134 | AZ9: 122 | BA9: 119 | BB9: 125 | BC9: 125 | BD9: 118 | BE9: 113 | BF9: 107 | BG9: 98.3 | BH9: 84.3 | BI9: 85.3 | BJ9: 85.3 | BK9: 85.3 | BL9: 84.3 | BM9: 84.3 | BN9: 81.3 | BO9: 81.3 | BP9: 81.3 | BQ9: 82.3 | BR9: {=INDEX('DOWN 가격동향'!$DD$10:$AHC$10,MATCH(1,('DOWN 가격동향'!$K$8:$AHC$8='동향 그래프 ~시세반영 '!$A9)*('DOWN 가격동향'!$DD$9:$AHC$9='동향 그래프 ~시세반영 '!BR$3),0))} -> 82.3 | BS9: {=INDEX('DOWN 가격동향'!$DD$10:$AHC$10,MATCH(1,('DOWN 가격동향'!$K$8:$AHC$8='동향 그래프 ~시세반영 '!$A9)*('DOWN 가격동향'!$DD$9:$AHC$9='동향 그래프 ~시세반영 '!BS$3),0))} -> 89.3 | BT9: {=INDEX('DOWN 가격동향'!$DD$10:$AHC$10,MATCH(1,('DOWN 가격동향'!$K$8:$AHC$8='동향 그래프 ~시세반영 '!$A9)*('DOWN 가격동향'!$DD$9:$AHC$9='동향 그래프 ~시세반영 '!BT$3),0))} -> 89.3 | BU9: {=INDEX('DOWN 가격동향'!$DD$10:$AHC$10,MATCH(1,('DOWN 가격동향'!$K$8:$AHC$8='동향 그래프 ~시세반영 '!$A9)*('DOWN 가격동향'!$DD$9:$AHC$9='동향 그래프 ~시세반영 '!BU$3),0))} -> 88.3 | BV9: {=INDEX('DOWN 가격동향'!$DD$10:$AHC$10,MATCH(1,('DOWN 가격동향'!$K$8:$AHC$8='동향 그래프 ~시세반영 '!$A9)*('DOWN 가격동향'!$DD$9:$AHC$9='동향 그래프 ~시세반영 '!BV$3),0))} -> 88.3 | BW9: {=INDEX('DOWN 가격동향'!$DD$10:$AHC$10,MATCH(1,('DOWN 가격동향'!$K$8:$AHC$8='동향 그래프 ~시세반영 '!$A9)*('DOWN 가격동향'!$DD$9:$AHC$9='동향 그래프 ~시세반영 '!BW$3),0))} -> 88.3 | BX9: {=INDEX('DOWN 가격동향'!$DD$10:$AHC$10,MATCH(1,('DOWN 가격동향'!$K$8:$AHC$8='동향 그래프 ~시세반영 '!$A9)*('DOWN 가격동향'!$DD$9:$AHC$9='동향 그래프 ~시세반영 '!BX$3),0))} -> 89.3 | BY9: {=INDEX('DOWN 가격동향'!$DD$10:$AHC$10,MATCH(1,('DOWN 가격동향'!$K$8:$AHC$8='동향 그래프 ~시세반영 '!$A9)*('DOWN 가격동향'!$DD$9:$AHC$9='동향 그래프 ~시세반영 '!BY$3),0))} -> 89.3 | BZ9: 88.3 | CA9: 88.3 | CB9: 88.3 | CC9: 88.3 | CD9: 92.3 | CE9: 92.3 | CF9: 88.3 | CG9: 84.3 | CH9: 84.3 | CI9: 83 | CJ9: 83 | CK9: 85 | CL9: 92 | CM9: 95 | CN9: 95 | CO9: 95 | CP9: 95 | CQ9: 96 | CR9: 96 | CS9: 101 | CT9: 105 | CU9: {=INDEX('DOWN 가격동향'!10:10,MATCH(1,('DOWN 가격동향'!8:8='동향 그래프 ~시세반영 '!A9)*('DOWN 가격동향'!9:9='동향 그래프 ~시세반영 '!$CU3),0))} -> 105
A10: 남부다운 | BW10: {=INDEX('DOWN 가격동향'!$DD$10:$AHC$10,MATCH(1,('DOWN 가격동향'!$DD$8:$AHC$8='동향 그래프 ~시세반영 '!$A10)*('DOWN 가격동향'!$DD$9:$AHC$9='동향 그래프 ~시세반영 '!BW$3),0))} -> 80 | BX10: {=INDEX('DOWN 가격동향'!$DD$10:$AHC$10,MATCH(1,('DOWN 가격동향'!$DD$8:$AHC$8='동향 그래프 ~시세반영 '!$A10)*('DOWN 가격동향'!$DD$9:$AHC$9='동향 그래프 ~시세반영 '!BX$3),0))} -> 80 | BY10: 81.5 | BZ10: {=INDEX('DOWN 가격동향'!$DD$10:$AHC$10,MATCH(1,('DOWN 가격동향'!$K$8:$AHC$8='동향 그래프 ~시세반영 '!$A9)*('DOWN 가격동향'!$DD$9:$AHC$9='동향 그래프 ~시세반영 '!BZ$3),0))} -> 81.5 | CA10: {=INDEX('DOWN 가격동향'!$DD$10:$AHC$10,MATCH(1,('DOWN 가격동향'!$K$8:$AHC$8='동향 그래프 ~시세반영 '!$A9)*('DOWN 가격동향'!$DD$9:$AHC$9='동향 그래프 ~시세반영 '!CA$3),0))} -> 81 | CB10: {=INDEX('DOWN 가격동향'!$DD$10:$AHC$10,MATCH(1,('DOWN 가격동향'!$K$8:$AHC$8='동향 그래프 ~시세반영 '!$A9)*('DOWN 가격동향'!$DD$9:$AHC$9='동향 그래프 ~시세반영 '!CB$3),0))} -> 83.5 | CC10: {=INDEX('DOWN 가격동향'!$DD$10:$AHC$10,MATCH(1,('DOWN 가격동향'!$K$8:$AHC$8='동향 그래프 ~시세반영 '!$A9)*('DOWN 가격동향'!$DD$9:$AHC$9='동향 그래프 ~시세반영 '!CC$3),0))} -> 92 | CD10: {=INDEX('DOWN 가격동향'!$DD$10:$AHC$10,MATCH(1,('DOWN 가격동향'!$K$8:$AHC$8='동향 그래프 ~시세반영 '!$A9)*('DOWN 가격동향'!$DD$9:$AHC$9='동향 그래프 ~시세반영 '!CD$3),0))} -> 89 | CE10: {=INDEX('DOWN 가격동향'!$DD$10:$AHC$10,MATCH(1,('DOWN 가격동향'!$K$8:$AHC$8='동향 그래프 ~시세반영 '!$A9)*('DOWN 가격동향'!$DD$9:$AHC$9='동향 그래프 ~시세반영 '!CE$3),0))} -> 90 | CF10: {=INDEX('DOWN 가격동향'!$DD$10:$AHC$10,MATCH(1,('DOWN 가격동향'!$K$8:$AHC$8='동향 그래프 ~시세반영 '!$A9)*('DOWN 가격동향'!$DD$9:$AHC$9='동향 그래프 ~시세반영 '!CF$3),0))} -> 88 | CG10: {=INDEX('DOWN 가격동향'!$DD$10:$AHC$10,MATCH(1,('DOWN 가격동향'!$K$8:$AHC$8='동향 그래프 ~시세반영 '!$A9)*('DOWN 가격동향'!$DD$9:$AHC$9='동향 그래프 ~시세반영 '!CG$3),0))} -> 77 | ... CT10: {=INDEX('DOWN 가격동향'!$DD$10:$AHC$10,MATCH(1,('DOWN 가격동향'!$K$8:$AHC$8='동향 그래프 ~시세반영 '!$A9)*('DOWN 가격동향'!$DD$9:$AHC$9='동향 그래프 ~시세반영 '!CT$3),0))} -> 91.5 | CU10: {=INDEX('DOWN 가격동향'!10:10,MATCH(1,('DOWN 가격동향'!8:8='동향 그래프 ~시세반영 '!A10)*('DOWN 가격동향'!9:9='동향 그래프 ~시세반영 '!$CU3),0))} -> 95
A11: LY인터내셔널 | CF11: 92.3 | CG11: 92.3 | CH11: 85 | CI11: 87 | CJ11: 84.5 | CK11: 84.5 | CL11: 89 | CM11: 94.2 | CN11: 107 | CO11: 108.6 | CP11: 111.5 | CQ11: 108 | CR11: 106 | CS11: 101.5 | CT11: 101.5 | CU11: {=INDEX('DOWN 가격동향'!10:10,MATCH(1,('DOWN 가격동향'!8:8='동향 그래프 ~시세반영 '!A11)*('DOWN 가격동향'!9:9='동향 그래프 ~시세반영 '!$CU3),0))} -> 105.5
A12: GQ다운 | CU12: {=INDEX('DOWN 가격동향'!10:10,MATCH(1,('DOWN 가격동향'!8:8='동향 그래프 ~시세반영 '!A12)*('DOWN 가격동향'!9:9='동향 그래프 ~시세반영 '!$CU3),0))} -> 91.4 | CX12: 부킹가 | CY12: 대비
A13: RDS CHINA GOOSE DOWN 80/20 GREY 650FP+ | B13: =AVERAGE(B4:B9) -> 68.816667 | C13: =AVERAGE(C4:C9) -> 69.8 | D13: =AVERAGE(D4:D9) -> 70.383333 | E13: =AVERAGE(E4:E9) -> 72.066667 | F13: =AVERAGE(F4:F9) -> 72.566667 | G13: =AVERAGE(G4:G9) -> 72.06 | H13: =AVERAGE(H4:H9) -> 73.191667 | I13: =AVERAGE(I4:I9) -> 72.941667 | ... BQ13: =AVERAGE(BQ4:BQ9) -> 83.066667 | BR13: =AVERAGEIF(BR4:BR9,">0") -> 85.833333 | BS13: =AVERAGEIF(BS4:BS9,">0") -> 87.333333 | BT13: =AVERAGEIF(BT4:BT9,">0") -> 86.766667 | BU13: =AVERAGEIF(BU4:BU9,">0") -> 85.133333 | BV13: =AVERAGEIF(BV4:BV9,">0") -> 82.45 | BW13: =AVERAGEIF(BW4:BW10,">0") -> 82.1 | BX13: =AVERAGEIF(BX4:BX10,">0") -> 83.6 | BY13: =AVERAGEIF(BY4:BY10,">0") -> 85.014286 | BZ13: =AVERAGEIF(BZ4:BZ10,">0") -> 82.728571 | CA13: =AVERAGEIF(CA4:CA10,">0") -> 82.8 | CB13: =AVERAGEIF(CB4:CB10,">0") -> 85.542857 | CC13: =AVERAGEIF(CC4:CC10,">0") -> 88.685714 | CD13: =AVERAGEIF(CD4:CD10,">0") -> 89.457143 | CE13: =AVERAGEIF(CE4:CE11,">0") -> 89.471429 | CF13: =AVERAGEIF(CF4:CF11,">0") -> 87.485 | CG13: =AVERAGEIF(CG4:CG11,">0") -> 84.86 | CH13: =AVERAGEIF(CH4:CH11,">0") -> 84.04625 | CI13: =AVERAGEIF(CI4:CI11,">0") -> 85.3425 | CJ13: =AVERAGEIF(CJ4:CJ11,">0") -> 85.63 | CK13: =AVERAGEIF(CK4:CK11,">0") -> 86.9425 | CL13: =AVERAGEIF(CL4:CL11,">0") -> 92.9825 | ... CT13: =AVERAGEIF(CT4:CT11,">0") -> 102.04286 | CU13: =AVERAGEIF(CU4:CU12,">0") -> 102.8875 | CX13: 75.5 | CY13: =(CU13-CX13)/CX13 -> 0.36274834
C31: 23FW 선기획부킹 $63.24 (8/10) | L31: 23FW 부킹 $63.5(12/15)
Y34: 38.2 | Z34: 56.7 | AA34: =(Y34-Z34)/Y34 -> -0.48429319 | AB34: 37.9 | AC34: 56.5 | AD34: =(AB34-AC34)/AB34 -> -0.49076517
O35: 23년 | AL35: 24년 | CF35: 12월평균 | CG35: =AVERAGE(CF45:CG45) -> 52.31
A36: 업체명 | B36: 44747 | C36: 44761 | D36: 44783 | E36: 44797 | F36: 44811 | G36: =G3 -> 45191 | H36: =H3 -> 45204 | I36: =I3 -> 45221 | J36: =J3 -> 45232 | K36: =K3 -> 45246 | L36: =L3 -> 45260 | M36: =M3 -> 45273 | N36: =N3 -> 45287 | ... BG36: =BG3 -> 45623 | BH36: 45639 | BI36: 45653 | BJ36: 45666 | BK36: 45701 | BL36: 45716 | BM36: 45729 | BN36: 45757 | BO36: 45764 | BP36: 45778 | BQ36: 45793 | BR36: 45806 | BS36: 45820 | BT36: 45833 | BU36: 45848 | BV36: 45862 | BW36: 45876 | BX36: 45890 | BY36: 45904 | BZ36: 45917 | CA36: 45932 | CB36: 45946 | CC36: 45959 | CD36: 45975 | CE36: 45988 | CF36: 46002 | CG36: 46020 | CH36: 46031 | CI36: 46051 | CJ36: 46057 | CK36: 46073 | CL36: 46093 | CM36: 46114 | CN36: 46132 | CO36: 46142 | CP36: 46163 | CQ36: 46192 | CR36: =CR3 -> 46212 | CS36: =CS3 -> 46233 | CT36: =CT3 -> 46247 | CU36: =CU3 -> 46269
A37: PCK | B37: 39 | C37: 38.5 | D37: 41.5 | E37: 41.5 | F37: 41.5 | G37: 41.5 | H37: 39 | I37: 38.5 | J37: 37.5 | K37: 36.9 | L37: 35.5 | M37: 35.5 | N37: 35.5 | O37: 35.5 | P37: 35.5 | Q37: 35.5 | R37: 36.5 | S37: 38.5 | T37: 37.5 | U37: 35.5 | V37: 35 | W37: 34.5 | X37: 34.5 | Y37: 34 | Z37: 34.5 | AA37: 34.5 | AB37: 34.5 | AC37: 34 | AD37: 34 | AE37: 34 | AF37: 34 | AG37: 34.5 | AH37: 34.5 | AI37: 36 | AJ37: 38 | AK37: 38 | AL37: 36 | AM37: 37 | AN37: 38 | AO37: 40 | AP37: 45 | AQ37: 46 | AR37: 42 | AS37: 42 | AT37: 42 | AU37: 45 | AV37: 48 | AW37: 50 | AX37: 50 | AY37: 50 | AZ37: 50 | BA37: 50 | BB37: 50 | BC37: 53 | BD37: 55 | BE37: 54 | BF37: 52 | BG37: 49 | BH37: 45 | BI37: 47 | BJ37: 45 | BK37: 45 | BL37: 44 | BM37: 43 | BN37: 42 | BO37: 42 | BP37: 42 | BQ37: 41 | BR37: {=INDEX('DOWN 가격동향'!$DD$11:$AHC$11,MATCH(1,('DOWN 가격동향'!$K$8:$AHC$8='동향 그래프 ~시세반영 '!$A37)*('DOWN 가격동향'!$DD$9:$AHC$9='동향 그래프 ~시세반영 '!BR$3),0))} -> 41 | BS37: {=INDEX('DOWN 가격동향'!$DD$11:$AHC$11,MATCH(1,('DOWN 가격동향'!$K$8:$AHC$8='동향 그래프 ~시세반영 '!$A37)*('DOWN 가격동향'!$DD$9:$AHC$9='동향 그래프 ~시세반영 '!BS$3),0))} -> 42 | BT37: {=INDEX('DOWN 가격동향'!$DD$11:$AHC$11,MATCH(1,('DOWN 가격동향'!$K$8:$AHC$8='동향 그래프 ~시세반영 '!$A37)*('DOWN 가격동향'!$DD$9:$AHC$9='동향 그래프 ~시세반영 '!BT$3),0))} -> 44 | BU37: {=INDEX('DOWN 가격동향'!$DD$11:$AHC$11,MATCH(1,('DOWN 가격동향'!$K$8:$AHC$8='동향 그래프 ~시세반영 '!$A37)*('DOWN 가격동향'!$DD$9:$AHC$9='동향 그래프 ~시세반영 '!BU$3),0))} -> 41 | BV37: {=INDEX('DOWN 가격동향'!$DD$11:$AHC$11,MATCH(1,('DOWN 가격동향'!$K$8:$AHC$8='동향 그래프 ~시세반영 '!$A37)*('DOWN 가격동향'!$DD$9:$AHC$9='동향 그래프 ~시세반영 '!BV$3),0))} -> 45 | BW37: {=INDEX('DOWN 가격동향'!$DD$11:$AHC$11,MATCH(1,('DOWN 가격동향'!$K$8:$AHC$8='동향 그래프 ~시세반영 '!$A37)*('DOWN 가격동향'!$DD$9:$AHC$9='동향 그래프 ~시세반영 '!BW$3),0))} -> 46 | BX37: {=INDEX('DOWN 가격동향'!$DD$11:$AHC$11,MATCH(1,('DOWN 가격동향'!$K$8:$AHC$8='동향 그래프 ~시세반영 '!$A37)*('DOWN 가격동향'!$DD$9:$AHC$9='동향 그래프 ~시세반영 '!BX$3),0))} -> 47 | BY37: {=INDEX('DOWN 가격동향'!$DD$11:$AHC$11,MATCH(1,('DOWN 가격동향'!$K$8:$AHC$8='동향 그래프 ~시세반영 '!$A37)*('DOWN 가격동향'!$DD$9:$AHC$9='동향 그래프 ~시세반영 '!BY$3),0))} -> 47 | ... CU37: {=INDEX('DOWN 가격동향'!$DD$11:$AHC$11,MATCH(1,('DOWN 가격동향'!$K$8:$AHC$8='동향 그래프 ~시세반영 '!$A37)*('DOWN 가격동향'!$DD$9:$AHC$9='동향 그래프 ~시세반영 '!CU$3),0))} -> 60
A38: 광륭 | B38: 44.5 | C38: 46 | D38: 48 | E38: 50 | F38: 50 | G38: 43.5 | H38: 38.5 | I38: 36.7 | J38: 34.8 | K38: 34.6 | L38: 34.6 | M38: 35.8 | N38: 35.8 | O38: 38 | P38: 38 | Q38: 40 | R38: 49 | S38: 51 | T38: 50 | U38: 48 | V38: 50 | W38: 50 | X38: 49.5 | Y38: 44.5 | Z38: 44.5 | AA38: 44.1 | AB38: 44.1 | AC38: 43.7 | AD38: 44 | AE38: 44 | AF38: 44 | AG38: 44 | AH38: 43.5 | AI38: 38 | AJ38: 42 | AK38: 42 | AL38: 42 | AM38: 41 | AN38: 49 | AO38: 53 | AP38: 54.5 | AQ38: 54 | AR38: 53 | AS38: 53.5 | AT38: 49.5 | AU38: 49.5 | AV38: 58 | AW38: 59 | AX38: 58 | AY38: 59 | AZ38: 56 | BA38: 55 | BB38: 55.5 | BC38: 58 | BD38: 58 | BE38: 58 | BF38: 55 | BG38: 48 | BH38: 49 | BI38: 51 | BJ38: 51 | BK38: 50 | BL38: 48 | BM38: 48 | BN38: 47 | BO38: 47 | BP38: 47 | BQ38: 45.8 | BR38: {=INDEX('DOWN 가격동향'!$DD$11:$AHC$11,MATCH(1,('DOWN 가격동향'!$K$8:$AHC$8='동향 그래프 ~시세반영 '!$A38)*('DOWN 가격동향'!$DD$9:$AHC$9='동향 그래프 ~시세반영 '!BR$3),0))} -> 44.5 | BS38: {=INDEX('DOWN 가격동향'!$DD$11:$AHC$11,MATCH(1,('DOWN 가격동향'!$K$8:$AHC$8='동향 그래프 ~시세반영 '!$A38)*('DOWN 가격동향'!$DD$9:$AHC$9='동향 그래프 ~시세반영 '!BS$3),0))} -> 46.5 | BT38: {=INDEX('DOWN 가격동향'!$DD$11:$AHC$11,MATCH(1,('DOWN 가격동향'!$K$8:$AHC$8='동향 그래프 ~시세반영 '!$A38)*('DOWN 가격동향'!$DD$9:$AHC$9='동향 그래프 ~시세반영 '!BT$3),0))} -> 50.5 | BU38: {=INDEX('DOWN 가격동향'!$DD$11:$AHC$11,MATCH(1,('DOWN 가격동향'!$K$8:$AHC$8='동향 그래프 ~시세반영 '!$A38)*('DOWN 가격동향'!$DD$9:$AHC$9='동향 그래프 ~시세반영 '!BU$3),0))} -> 48.5 | BV38: {=INDEX('DOWN 가격동향'!$DD$11:$AHC$11,MATCH(1,('DOWN 가격동향'!$K$8:$AHC$8='동향 그래프 ~시세반영 '!$A38)*('DOWN 가격동향'!$DD$9:$AHC$9='동향 그래프 ~시세반영 '!BV$3),0))} -> 45.5 | BW38: {=INDEX('DOWN 가격동향'!$DD$11:$AHC$11,MATCH(1,('DOWN 가격동향'!$K$8:$AHC$8='동향 그래프 ~시세반영 '!$A38)*('DOWN 가격동향'!$DD$9:$AHC$9='동향 그래프 ~시세반영 '!BW$3),0))} -> 45.5 | BX38: {=INDEX('DOWN 가격동향'!$DD$11:$AHC$11,MATCH(1,('DOWN 가격동향'!$K$8:$AHC$8='동향 그래프 ~시세반영 '!$A38)*('DOWN 가격동향'!$DD$9:$AHC$9='동향 그래프 ~시세반영 '!BX$3),0))} -> 47 | BY38: {=INDEX('DOWN 가격동향'!$DD$11:$AHC$11,MATCH(1,('DOWN 가격동향'!$K$8:$AHC$8='동향 그래프 ~시세반영 '!$A38)*('DOWN 가격동향'!$DD$9:$AHC$9='동향 그래프 ~시세반영 '!BY$3),0))} -> 48 | ... CU38: {=INDEX('DOWN 가격동향'!$DD$11:$AHC$11,MATCH(1,('DOWN 가격동향'!$K$8:$AHC$8='동향 그래프 ~시세반영 '!$A38)*('DOWN 가격동향'!$DD$9:$AHC$9='동향 그래프 ~시세반영 '!CU$3),0))} -> 64.5
A39: 다음앤큐큐 | B39: 39.3 | C39: 39.3 | D39: 39.3 | E39: 39.3 | F39: 39.3 | G39: 41.3 | H39: 39.3 | I39: 38.8 | J39: 34.3 | K39: 34.3 | L39: 34.3 | M39: 33.3 | N39: 33.3 | O39: 33.3 | P39: 33.3 | Q39: 40.3 | R39: 40.3 | S39: 37.3 | T39: 39.3 | U39: 39.3 | V39: 39.3 | W39: 39.3 | X39: 39.3 | Y39: 39.3 | Z39: 39.5 | AA39: 39.5 | AB39: 39.5 | AC39: 37.3 | AD39: 37.3 | AE39: 37.3 | AF39: 36 | AG39: 35 | AH39: 35 | AI39: 36 | AJ39: 38 | AK39: 38 | AL39: 37 | AM39: 45 | AN39: 48 | AO39: 48 | AP39: 49 | AQ39: 50 | AR39: 48 | AS39: 48 | AT39: 48 | AU39: 49 | AV39: 55 | AW39: 55 | AX39: 58 | AY39: 56 | AZ39: 53 | BA39: 51 | BB39: 51 | BC39: 53 | BD39: 52 | BE39: 52 | BF39: 51 | BG39: 48 | BH39: 43.3 | BI39: 45.3 | BJ39: 44.3 | BK39: 44.3 | BL39: 44.3 | BM39: 44.3 | BN39: 43 | BO39: 40.3 | BP39: 41.3 | BQ39: 42.3 | BR39: {=INDEX('DOWN 가격동향'!$DD$11:$AHC$11,MATCH(1,('DOWN 가격동향'!$K$8:$AHC$8='동향 그래프 ~시세반영 '!$A39)*('DOWN 가격동향'!$DD$9:$AHC$9='동향 그래프 ~시세반영 '!BR$3),0))} -> 45.1 | BS39: {=INDEX('DOWN 가격동향'!$DD$11:$AHC$11,MATCH(1,('DOWN 가격동향'!$K$8:$AHC$8='동향 그래프 ~시세반영 '!$A39)*('DOWN 가격동향'!$DD$9:$AHC$9='동향 그래프 ~시세반영 '!BS$3),0))} -> 48.3 | BT39: {=INDEX('DOWN 가격동향'!$DD$11:$AHC$11,MATCH(1,('DOWN 가격동향'!$K$8:$AHC$8='동향 그래프 ~시세반영 '!$A39)*('DOWN 가격동향'!$DD$9:$AHC$9='동향 그래프 ~시세반영 '!BT$3),0))} -> 48.3 | BU39: {=INDEX('DOWN 가격동향'!$DD$11:$AHC$11,MATCH(1,('DOWN 가격동향'!$K$8:$AHC$8='동향 그래프 ~시세반영 '!$A39)*('DOWN 가격동향'!$DD$9:$AHC$9='동향 그래프 ~시세반영 '!BU$3),0))} -> 43.3 | BV39: {=INDEX('DOWN 가격동향'!$DD$11:$AHC$11,MATCH(1,('DOWN 가격동향'!$K$8:$AHC$8='동향 그래프 ~시세반영 '!$A39)*('DOWN 가격동향'!$DD$9:$AHC$9='동향 그래프 ~시세반영 '!BV$3),0))} -> 44.3 | BW39: {=INDEX('DOWN 가격동향'!$DD$11:$AHC$11,MATCH(1,('DOWN 가격동향'!$K$8:$AHC$8='동향 그래프 ~시세반영 '!$A39)*('DOWN 가격동향'!$DD$9:$AHC$9='동향 그래프 ~시세반영 '!BW$3),0))} -> 44.3 | BX39: {=INDEX('DOWN 가격동향'!$DD$11:$AHC$11,MATCH(1,('DOWN 가격동향'!$K$8:$AHC$8='동향 그래프 ~시세반영 '!$A39)*('DOWN 가격동향'!$DD$9:$AHC$9='동향 그래프 ~시세반영 '!BX$3),0))} -> 44.3 | BY39: {=INDEX('DOWN 가격동향'!$DD$11:$AHC$11,MATCH(1,('DOWN 가격동향'!$K$8:$AHC$8='동향 그래프 ~시세반영 '!$A39)*('DOWN 가격동향'!$DD$9:$AHC$9='동향 그래프 ~시세반영 '!BY$3),0))} -> 44.3 | ... CU39: {=INDEX('DOWN 가격동향'!$DD$11:$AHC$11,MATCH(1,('DOWN 가격동향'!$K$8:$AHC$8='동향 그래프 ~시세반영 '!$A39)*('DOWN 가격동향'!$DD$9:$AHC$9='동향 그래프 ~시세반영 '!CU$3),0))} -> 0
A40: ALLIED | B40: 38.6 | C40: 37.7 | D40: 40.3 | E40: 40.3 | F40: 39.3 | G40: 39.34 | H40: 37.9 | I40: 36.14 | J40: 33.9 | K40: 34.14 | L40: 33.9 | M40: 32.22 | N40: 36.54 | O40: 36.54 | P40: 36.54 | Q40: 41.5 | R40: 40.2 | S40: 40.2 | T40: 39.6 | U40: 38.8 | V40: 38.8 | W40: 38.5 | X40: 38 | Y40: 37 | Z40: 37 | AA40: 36.9 | AB40: 36.9 | AC40: 37 | AD40: 37 | AE40: 37 | AF40: 36.3 | AG40: 36.3 | AH40: 36.3 | AI40: 40.6 | AJ40: 42.4 | AK40: 42.4 | AL40: 43.7 | AM40: 45.6 | AN40: 45.6 | AO40: 48.9 | AP40: 48.9 | AQ40: 50.1 | AR40: 51 | AS40: 51 | AT40: 51.8 | AU40: 51.8 | AV40: 59.1 | AW40: 59.1 | AX40: 59.1 | AY40: 59.1 | AZ40: 59.1 | BA40: 55.1 | BB40: 55.1 | BC40: 57.8 | BD40: 57.8 | BE40: 57.7 | BF40: 49.3 | BG40: 49.4 | BH40: 41.3 | BI40: 41.3 | BJ40: 41.3 | BK40: 41.3 | BL40: 41.3 | BM40: 41.3 | BN40: 40.8 | BO40: 40.8 | BP40: 40.8 | BQ40: 40.8 | BR40: {=INDEX('DOWN 가격동향'!$DD$11:$AHC$11,MATCH(1,('DOWN 가격동향'!$K$8:$AHC$8='동향 그래프 ~시세반영 '!$A40)*('DOWN 가격동향'!$DD$9:$AHC$9='동향 그래프 ~시세반영 '!BR$3),0))} -> 46.4 | BS40: {=INDEX('DOWN 가격동향'!$DD$11:$AHC$11,MATCH(1,('DOWN 가격동향'!$K$8:$AHC$8='동향 그래프 ~시세반영 '!$A40)*('DOWN 가격동향'!$DD$9:$AHC$9='동향 그래프 ~시세반영 '!BS$3),0))} -> 46.4 | BT40: {=INDEX('DOWN 가격동향'!$DD$11:$AHC$11,MATCH(1,('DOWN 가격동향'!$K$8:$AHC$8='동향 그래프 ~시세반영 '!$A40)*('DOWN 가격동향'!$DD$9:$AHC$9='동향 그래프 ~시세반영 '!BT$3),0))} -> 46.4 | BU40: {=INDEX('DOWN 가격동향'!$DD$11:$AHC$11,MATCH(1,('DOWN 가격동향'!$K$8:$AHC$8='동향 그래프 ~시세반영 '!$A40)*('DOWN 가격동향'!$DD$9:$AHC$9='동향 그래프 ~시세반영 '!BU$3),0))} -> 41.3 | BV40: {=INDEX('DOWN 가격동향'!$DD$11:$AHC$11,MATCH(1,('DOWN 가격동향'!$K$8:$AHC$8='동향 그래프 ~시세반영 '!$A40)*('DOWN 가격동향'!$DD$9:$AHC$9='동향 그래프 ~시세반영 '!BV$3),0))} -> 44.8 | BW40: {=INDEX('DOWN 가격동향'!$DD$11:$AHC$11,MATCH(1,('DOWN 가격동향'!$K$8:$AHC$8='동향 그래프 ~시세반영 '!$A40)*('DOWN 가격동향'!$DD$9:$AHC$9='동향 그래프 ~시세반영 '!BW$3),0))} -> 44.8 | BX40: {=INDEX('DOWN 가격동향'!$DD$11:$AHC$11,MATCH(1,('DOWN 가격동향'!$K$8:$AHC$8='동향 그래프 ~시세반영 '!$A40)*('DOWN 가격동향'!$DD$9:$AHC$9='동향 그래프 ~시세반영 '!BX$3),0))} -> 46.4 | BY40: {=INDEX('DOWN 가격동향'!$DD$11:$AHC$11,MATCH(1,('DOWN 가격동향'!$K$8:$AHC$8='동향 그래프 ~시세반영 '!$A40)*('DOWN 가격동향'!$DD$9:$AHC$9='동향 그래프 ~시세반영 '!BY$3),0))} -> 49.6 | ... CU40: {=INDEX('DOWN 가격동향'!$DD$11:$AHC$11,MATCH(1,('DOWN 가격동향'!$K$8:$AHC$8='동향 그래프 ~시세반영 '!$A40)*('DOWN 가격동향'!$DD$9:$AHC$9='동향 그래프 ~시세반영 '!CU$3),0))} -> 61.4
A41: 태평양 | B41: 41.1 | C41: 41.1 | D41: 40.6 | E41: 41.6 | F41: 41.6 | G41: 41.6 | H41: 39 | I41: 39 | J41: 38.3 | K41: 35.3 | L41: 35.3 | M41: 35.3 | N41: 35.3 | O41: 34.3 | P41: 34.3 | Q41: 34.3 | R41: 35.3 | S41: 39.3 | T41: 35.3 | U41: 35.3 | V41: 35.3 | W41: 35.3 | X41: 35.3 | Y41: 36.3 | Z41: 37 | AA41: 37 | AB41: 37 | AC41: 36.3 | AD41: 36.3 | AE41: 36.3 | AF41: 36.3 | AG41: 36.3 | AH41: 36.3 | AI41: 36.3 | AJ41: 37.3 | AK41: 37.3 | AL41: 38.3 | AM41: 42 | AN41: 44 | AO41: 44 | AP41: 44 | AQ41: 44 | AR41: 45 | AS41: 45 | AT41: 45 | AU41: 49 | AV41: 53 | AW41: 53 | AX41: 56 | AY41: 56 | AZ41: 60 | BA41: 60 | BB41: 60 | BC41: 60 | BD41: 55 | BE41: 52.3 | BF41: 51.3 | BG41: 46.5 | BH41: 46 | BI41: 46 | BJ41: 46 | BK41: 46.3 | BL41: 46.3 | BM41: 45.8 | BN41: 43.3 | BO41: 44.3 | BP41: 44.8 | BQ41: 44.8 | BR41: {=INDEX('DOWN 가격동향'!$DD$11:$AHC$11,MATCH(1,('DOWN 가격동향'!$K$8:$AHC$8='동향 그래프 ~시세반영 '!$A41)*('DOWN 가격동향'!$DD$9:$AHC$9='동향 그래프 ~시세반영 '!BR$3),0))} -> 52.3 | BS41: {=INDEX('DOWN 가격동향'!$DD$11:$AHC$11,MATCH(1,('DOWN 가격동향'!$K$8:$AHC$8='동향 그래프 ~시세반영 '!$A41)*('DOWN 가격동향'!$DD$9:$AHC$9='동향 그래프 ~시세반영 '!BS$3),0))} -> 52.3 | BT41: {=INDEX('DOWN 가격동향'!$DD$11:$AHC$11,MATCH(1,('DOWN 가격동향'!$K$8:$AHC$8='동향 그래프 ~시세반영 '!$A41)*('DOWN 가격동향'!$DD$9:$AHC$9='동향 그래프 ~시세반영 '!BT$3),0))} -> 49.8 | BU41: {=INDEX('DOWN 가격동향'!$DD$11:$AHC$11,MATCH(1,('DOWN 가격동향'!$K$8:$AHC$8='동향 그래프 ~시세반영 '!$A41)*('DOWN 가격동향'!$DD$9:$AHC$9='동향 그래프 ~시세반영 '!BU$3),0))} -> 49.8 | BV41: {=INDEX('DOWN 가격동향'!$DD$11:$AHC$11,MATCH(1,('DOWN 가격동향'!$K$8:$AHC$8='동향 그래프 ~시세반영 '!$A41)*('DOWN 가격동향'!$DD$9:$AHC$9='동향 그래프 ~시세반영 '!BV$3),0))} -> 48.3 | BW41: {=INDEX('DOWN 가격동향'!$DD$11:$AHC$11,MATCH(1,('DOWN 가격동향'!$K$8:$AHC$8='동향 그래프 ~시세반영 '!$A41)*('DOWN 가격동향'!$DD$9:$AHC$9='동향 그래프 ~시세반영 '!BW$3),0))} -> 48.3 | BX41: {=INDEX('DOWN 가격동향'!$DD$11:$AHC$11,MATCH(1,('DOWN 가격동향'!$K$8:$AHC$8='동향 그래프 ~시세반영 '!$A41)*('DOWN 가격동향'!$DD$9:$AHC$9='동향 그래프 ~시세반영 '!BX$3),0))} -> 52.3 | BY41: {=INDEX('DOWN 가격동향'!$DD$11:$AHC$11,MATCH(1,('DOWN 가격동향'!$K$8:$AHC$8='동향 그래프 ~시세반영 '!$A41)*('DOWN 가격동향'!$DD$9:$AHC$9='동향 그래프 ~시세반영 '!BY$3),0))} -> 52.3 | ... CU41: {=INDEX('DOWN 가격동향'!$DD$11:$AHC$11,MATCH(1,('DOWN 가격동향'!$K$8:$AHC$8='동향 그래프 ~시세반영 '!$A41)*('DOWN 가격동향'!$DD$9:$AHC$9='동향 그래프 ~시세반영 '!CU$3),0))} -> 58.5
A42: 신주원 | B42: 41.3 | C42: 41.3 | D42: 41.3 | E42: 41.3 | F42: 41.3 | G42: 40.3 | H42: 40 | I42: 38.3 | J42: 36.8 | K42: 35.3 | L42: 34.3 | M42: 33 | N42: 35.3 | O42: 35.3 | P42: 33.3 | Q42: 34.3 | R42: 36.3 | S42: 38.3 | T42: 38.3 | U42: 38.3 | V42: 38 | W42: 38.3 | X42: 38.3 | Y42: 38.3 | Z42: 36.3 | AA42: 35.3 | AB42: 35.3 | AC42: 35.3 | AD42: 35.3 | AE42: 36.3 | AF42: 36.3 | AG42: 36.3 | AH42: 36.3 | AI42: 35.3 | AJ42: 36.3 | AK42: 39.3 | AL42: 42.3 | AM42: 42.3 | AN42: 51.3 | AO42: 53.3 | AP42: 53.3 | AQ42: 51.3 | AR42: 51.3 | AS42: 51.3 | AT42: 44 | AU42: 44 | AV42: 55 | AW42: 58 | AX42: 58 | AY42: 59 | AZ42: 54 | BA42: 53 | BB42: 55 | BC42: 55 | BD42: 53 | BE42: 53 | BF42: 50 | BG42: 48.3 | BH42: 43.3 | BI42: 44 | BJ42: 44 | BK42: 43.8 | BL42: 43.8 | BM42: 43.8 | BN42: 42.3 | BO42: 42.3 | BP42: 42.3 | BQ42: 43.3 | BR42: {=INDEX('DOWN 가격동향'!$DD$11:$AHC$11,MATCH(1,('DOWN 가격동향'!$K$8:$AHC$8='동향 그래프 ~시세반영 '!$A42)*('DOWN 가격동향'!$DD$9:$AHC$9='동향 그래프 ~시세반영 '!BR$3),0))} -> 43.3 | BS42: {=INDEX('DOWN 가격동향'!$DD$11:$AHC$11,MATCH(1,('DOWN 가격동향'!$K$8:$AHC$8='동향 그래프 ~시세반영 '!$A42)*('DOWN 가격동향'!$DD$9:$AHC$9='동향 그래프 ~시세반영 '!BS$3),0))} -> 43.5 | BT42: {=INDEX('DOWN 가격동향'!$DD$11:$AHC$11,MATCH(1,('DOWN 가격동향'!$K$8:$AHC$8='동향 그래프 ~시세반영 '!$A42)*('DOWN 가격동향'!$DD$9:$AHC$9='동향 그래프 ~시세반영 '!BT$3),0))} -> 43.8 | BU42: {=INDEX('DOWN 가격동향'!$DD$11:$AHC$11,MATCH(1,('DOWN 가격동향'!$K$8:$AHC$8='동향 그래프 ~시세반영 '!$A42)*('DOWN 가격동향'!$DD$9:$AHC$9='동향 그래프 ~시세반영 '!BU$3),0))} -> 42.8 | BV42: {=INDEX('DOWN 가격동향'!$DD$11:$AHC$11,MATCH(1,('DOWN 가격동향'!$K$8:$AHC$8='동향 그래프 ~시세반영 '!$A42)*('DOWN 가격동향'!$DD$9:$AHC$9='동향 그래프 ~시세반영 '!BV$3),0))} -> 43.3 | BW42: {=INDEX('DOWN 가격동향'!$DD$11:$AHC$11,MATCH(1,('DOWN 가격동향'!$K$8:$AHC$8='동향 그래프 ~시세반영 '!$A42)*('DOWN 가격동향'!$DD$9:$AHC$9='동향 그래프 ~시세반영 '!BW$3),0))} -> 44.3 | BX42: {=INDEX('DOWN 가격동향'!$DD$11:$AHC$11,MATCH(1,('DOWN 가격동향'!$K$8:$AHC$8='동향 그래프 ~시세반영 '!$A42)*('DOWN 가격동향'!$DD$9:$AHC$9='동향 그래프 ~시세반영 '!BX$3),0))} -> 47.8 | BY42: {=INDEX('DOWN 가격동향'!$DD$11:$AHC$11,MATCH(1,('DOWN 가격동향'!$K$8:$AHC$8='동향 그래프 ~시세반영 '!$A42)*('DOWN 가격동향'!$DD$9:$AHC$9='동향 그래프 ~시세반영 '!BY$3),0))} -> 47.8 | BZ42: 48.3 | CA42: 49.8 | CB42: 50.1 | CC42: 50.1 | CD42: 55 | CE42: 55 | CF42: 49.3 | CG42: 49.3 | CH42: 49.3 | CI42: 47 | CJ42: 47 | CK42: 50 | CL42: 55 | CM42: 55 | CN42: 59 | CO42: 59 | CP42: 59 | CQ42: 57 | CR42: 57 | CS42: 57 | CT42: 55 | CU42: {=INDEX('DOWN 가격동향'!11:11,MATCH(1,('DOWN 가격동향'!8:8='동향 그래프 ~시세반영 '!A42)*('DOWN 가격동향'!9:9='동향 그래프 ~시세반영 '!$CU36),0))} -> 55
A43: LY인터내셔널 | CF43: 57.5 | CG43: 57.5 | CH43: 53.5 | CI43: 56 | CJ43: 54.3 | CK43: 54.3 | CL43: 61 | CM43: 63.5 | CN43: 66.5 | CO43: 68.6 | CP43: 65 | CQ43: 63.5 | CR43: 64.5 | CS43: 62 | CT43: 62 | CU43: {=INDEX('DOWN 가격동향'!11:11,MATCH(1,('DOWN 가격동향'!8:8='동향 그래프 ~시세반영 '!A43)*('DOWN 가격동향'!9:9='동향 그래프 ~시세반영 '!$CU36),0))} -> 62
A44: GQ다운 | CU44: {=INDEX('DOWN 가격동향'!11:11,MATCH(1,('DOWN 가격동향'!8:8='동향 그래프 ~시세반영 '!A44)*('DOWN 가격동향'!9:9='동향 그래프 ~시세반영 '!$CU36),0))} -> 51.1
A45: RDS CHINA DUCK DOWN 80/20 GREY 600FP+ | B45: =AVERAGE(B37:B42) -> 40.633333 | C45: =AVERAGE(C37:C42) -> 40.65 | D45: =AVERAGE(D37:D42) -> 41.833333 | E45: =AVERAGE(E37:E42) -> 42.333333 | F45: =AVERAGE(F37:F42) -> 42.166667 | G45: =AVERAGE(G37:G42) -> 41.256667 | H45: =AVERAGE(H37:H42) -> 38.95 | I45: =AVERAGE(I37:I42) -> 37.906667 | ... BQ45: =AVERAGE(BQ37:BQ42) -> 43 | BR45: =AVERAGEIF(BR37:BR42,">0") -> 45.433333 | BS45: =AVERAGEIF(BS37:BS42,">0") -> 46.5 | BT45: =AVERAGEIF(BT37:BT42,">0") -> 47.133333 | BU45: =AVERAGEIF(BU37:BU42,">0") -> 44.45 | BV45: =AVERAGEIF(BV37:BV42,">0") -> 45.2 | BW45: =AVERAGEIF(BW37:BW42,">0") -> 45.533333 | BX45: =AVERAGEIF(BX37:BX42,">0") -> 47.466667 | BY45: =AVERAGEIF(BY37:BY42,">0") -> 48.166667 | ... CD45: =AVERAGEIF(CD37:CD42,">0") -> 55.466667 | CE45: =AVERAGEIF(CE37:CE43,">0") -> 54.85 | CF45: =AVERAGEIF(CF37:CF43,">0") -> 52.524286 | CG45: =AVERAGEIF(CG37:CG43,">0") -> 52.095714 | CH45: =AVERAGEIF(CH37:CH43,">0") -> 51.157143 | CI45: =AVERAGEIF(CI37:CI43,">0") -> 53.32 | CJ45: =AVERAGEIF(CJ37:CJ43,">0") -> 53.334286 | CK45: =AVERAGEIF(CK37:CK43,">0") -> 54.177143 | CL45: =AVERAGEIF(CL37:CL43,">0") -> 59.331429 | ... CT45: =AVERAGEIF(CT37:CT43,">0") -> 59.683333 | CU45: =AVERAGEIF(CU37:CU44,">0") -> 58.928571 | CX45: 부킹가 | CY45: 대비
CX46: 40 | CY46: =(CU45-CX46)/CX46 -> 0.47321429

Sheet DOWN 가격동향
ALH2: ORIGIN | ALI2: Commodity & Description | ALJ2: Color | ALK2: F.P | ALL2: 업체 | ALM2: PCK | ALN2: 광륭 | ALO2: 다음앤큐큐 | ALP2: ALLIED | ALQ2: 태평양 | ALR2: 신주원 | ALS2: 평균
ALL3: 날짜별 | ALM3: 45203 | ALN3: 45203 | ALO3: 45203 | ALP3: 45203 | ALQ3: 45203 | ALR3: 45203
ALH4: CHINA | ALI4: RDS CHINA GOOSE DOWN 80/20 | ALJ4: GREY | ALK4: 650 | ALL4: 9/26~10/10 | ALM4: 70.5 | ALN4: 74 | ALO4: 70.5 | ALP4: 76.3 | ALQ4: 76.3 | ALR4: 67 | ALS4: =AVERAGE(ALM4:ALR4) -> 72.433333
ALH5: CHINA | ALI5: RDS CHINA DUCK DOWN 80/20 20ton 기준 | ALJ5: GREY | ALK5: 600 | ALL5: 9/26~10/10 | ALM5: 32.9 | ALN5: 33.5 | ALO5: 34 | ALP5: 35.2 | ALQ5: 33.8 | ALR5: 33.5 | ALS5: =AVERAGE(ALM5:ALR5) -> 33.816667
A6: DOWN 시세 | AK6: RDS +$0.5 | AL6: RDS +$0.5 | AM6: RDS +$0.5 | AN6: RDS +$0.5 | AO6: RDS +$0.5 | AP6: RDS +$0.5 | AQ6: RDS +$0.5 | AR6: RDS +$0.5 | AS6: RDS +$0.5 | AT6: RDS +$0.5 | AU6: RDS +$0.5 | AV6: RDS +$0.5 | AW6: RDS +$0.5 | AX6: RDS +$0.5 | AY6: RDS +$0.5 | AZ6: RDS +$0.5 | BA6: RDS +$0.5 | BB6: RDS +$0.5 | BC6: RDS +$0.5 | BD6: RDS +$0.5 | BE6: RDS +$0.5 | BF6: RDS +$0.5 | BG6: RDS +$0.5 | BH6: RDS +$0.5 | BI6: RDS +$0.5 | BJ6: RDS +$0.5 | BK6: RDS +$0.5 | BL6: RDS +$0.5 | BM6: RDS +$0.5 | BN6: RDS +$0.5 | BO6: RDS +$0.5 | BP6: RDS +$0.5 | BQ6: RDS +$0.5 | BR6: RDS +$0.5 | BS6: RDS +$0.5 | BT6: RDS +$0.5 | BU6: RDS +$0.5 | BV6: RDS +$0.5 | BW6: RDS +$0.5 | BX6: RDS +$0.5 | BY6: RDS +$0.5 | BZ6: RDS +$0.5 | CA6: RDS +$0.5 | NI6: 동일 | NJ6: 동일 | NK6: 동일 | ZH6: 동일 | ZI6: 동일 | ZJ6: 동일 | AIC6: RDS +$0.5 | AID6: RDS +$0.5 | AIE6: RDS +$0.5 | AIF6: RDS +$0.5 | AIG6: RDS +$0.5 | AIH6: RDS +$0.5 | AII6: RDS +$0.5 | AIJ6: RDS +$0.5 | AIK6: RDS +$0.5 | AIL6: RDS +$0.5 | AIM6: RDS +$0.5 | AIN6: RDS +$0.5 | AIO6: RDS +$0.5 | AIP6: RDS +$0.5 | AIQ6: RDS +$0.5 | AIR6: RDS +$0.5 | AIS6: RDS +$0.5 | AIT6: RDS +$0.5 | AIU6: RDS +$0.5 | AIV6: RDS +$0.5 | AIW6: RDS +$0.5 | AIX6: RDS +$0.5 | AIY6: RDS +$0.5 | AIZ6: RDS +$0.5 | AJA6: RDS +$0.5 | AJB6: RDS +$0.5 | AJC6: RDS +$0.5 | AJD6: RDS +$0.5 | AJE6: RDS +$0.5 | AJF6: RDS +$0.5 | AJG6: RDS +$0.5 | AJH6: RDS +$0.5 | AJI6: RDS +$0.5 | AJJ6: RDS +$0.5 | AJK6: RDS +$0.5 | AJT6: RDS | AJU6: RDS | AJV6: RDS | AJW6: RDS | AJX6: RDS | AJY6: RDS | AJZ6: RDS | AKA6: RDS | AKB6: RDS | AKC6: RDS | AKD6: RDS | AKE6: RDS | AKF6: RDS
A7: ORIGIN | B7: Commodity & Description | C7: Color | D7: F.P | E7: 20FW BOOKING | H7: 21FW 진행가 | I7: 22FW 진행가 | J7: 22FW 진행수량 (KG) | AKP7: NO RDS | AKQ7: NO RDS | AKR7: NO RDS | AKS7: NO RDS | AKT7: RDS | AKU7: RDS | AKV7: NO RDS | AKW7: RDS | AKX7: RDS | AKY7: RDS | AKZ7: RDS | ALA7: RDS | ALB7: RDS | ALC7: RDS | ALD7: RDS
K8: PCK | L8: PCK | M8: PCK | N8: PCK | O8: PCK | P8: PCK | Q8: PCK | R8: PCK | S8: PCK | T8: PCK | U8: PCK | V8: PCK | W8: PCK | X8: PCK | Y8: PCK | Z8: PCK | AA8: PCK | AB8: PCK | AC8: PCK | AD8: PCK | AE8: PCK | AF8: PCK | AG8: PCK | AH8: PCK | AI8: PCK | AJ8: PCK | AK8: PCK | AL8: PCK | AM8: PCK | AN8: PCK | AO8: PCK | AP8: PCK | AQ8: PCK | AR8: PCK | AS8: PCK | AT8: PCK | AU8: PCK | AV8: PCK | AW8: PCK | AX8: PCK | AY8: PCK | AZ8: PCK | BA8: PCK | BB8: PCK | BC8: PCK | BD8: PCK | BE8: PCK | BF8: PCK | BG8: PCK | BH8: PCK | BI8: PCK | BJ8: PCK | BK8: PCK | BL8: PCK | BM8: PCK | BN8: PCK | BO8: PCK | BP8: PCK | BQ8: PCK | BR8: PCK | BS8: PCK | BT8: PCK | BU8: PCK | BV8: PCK | BW8: PCK | BX8: PCK | BY8: PCK | BZ8: PCK | CA8: PCK | CB8: PCK | CC8: PCK | CD8: PCK | CE8: PCK | CF8: PCK | CG8: PCK | CH8: PCK | CI8: PCK | CJ8: PCK | CK8: PCK | CL8: PCK | CM8: PCK | CN8: PCK | CO8: PCK | CP8: PCK | CQ8: PCK | CR8: PCK | CS8: PCK | CT8: PCK | CU8: PCK | CV8: PCK | CW8: PCK | CX8: PCK | CY8: PCK | CZ8: PCK | DA8: PCK | DB8: PCK | DC8: PCK | DD8: PCK | DE8: PCK | DF8: PCK | DG8: PCK | DH8: PCK | DI8: PCK | DJ8: PCK | DK8: PCK | DL8: PCK | EP8: PCK | EQ8: 광륭 | ER8: 광륭 | ES8: 광륭 | ET8: 광륭 | EU8: 광륭 | EV8: 광륭 | EW8: 광륭 | EX8: 광륭 | EY8: 광륭 | EZ8: 광륭 | FA8: 광륭 | FB8: 광륭 | FC8: 광륭 | FD8: 광륭 | FE8: 광륭 | FF8: 광륭 | FG8: 광륭 | FH8: 광륭 | FI8: 광륭 | FJ8: 광륭 | FK8: 광륭 | FL8: 광륭 | FM8: 광륭 | FN8: 광륭 | FO8: 광륭 | FP8: 광륭 | FQ8: 광륭 | FR8: 광륭 | FS8: 광륭 | FT8: 광륭 | FU8: 광륭 | FV8: 광륭 | FW8: 광륭 | FX8: 광륭 | FY8: 광륭 | FZ8: 광륭 | GA8: 광륭 | GB8: 광륭 | GC8: 광륭 | GD8: 광륭 | GE8: 광륭 | GF8: 광륭 | GG8: 광륭 | GH8: 광륭 | GI8: 광륭 | GJ8: 광륭 | GK8: 광륭 | GL8: 광륭 | GM8: 광륭 | GN8: 광륭 | GO8: 광륭 | GP8: 광륭 | GQ8: 광륭 | GR8: 광륭 | GS8: 광륭 | GT8: 광륭 | GU8: 광륭 | GV8: 광륭 | GW8: 광륭 | GX8: 광륭 | GY8: 광륭 | GZ8: 광륭 | HA8: 광륭 | HB8: 광륭 | HC8: 광륭 | HD8: 광륭 | HE8: 광륭 | HF8: 광륭 | HG8: 광륭 | HH8: 광륭 | HI8: 광륭 | HJ8: 광륭 | HK8: 광륭 | HL8: 광륭 | HM8: 광륭 | HN8: 광륭 | HO8: 광륭 | HP8: 광륭 | HQ8: 광륭 | HR8: 광륭 | HS8: 광륭 | HT8: 광륭 | HU8: 광륭 | HV8: 광륭 | HW8: 광륭 | HX8: 광륭 | HY8: 광륭 | HZ8: 광륭 | IA8: 광륭 | IB8: 광륭 | IC8: 광륭 | ID8: 광륭 | IE8: 광륭 | IF8: 광륭 | IG8: 광륭 | IH8: 광륭 | II8: 광륭 | IJ8: 광륭 | IK8: 광륭 | IL8: 광륭 | IM8: 광륭 | IN8: 광륭 | IO8: 광륭 | IP8: 광륭 | IQ8: 광륭 | IR8: 광륭 | JV8: 광륭 | JW8: 다음앤큐큐 | JX8: 다음앤큐큐 | JY8: 다음앤큐큐 | JZ8: 다음앤큐큐 | KA8: 다음앤큐큐 | KB8: 다음앤큐큐 | KC8: 다음앤큐큐 | KD8: 다음앤큐큐 | KE8: 다음앤큐큐 | KF8: 다음앤큐큐 | KG8: 다음앤큐큐 | KH8: 다음앤큐큐 | KI8: 다음앤큐큐 | KJ8: 다음앤큐큐 | KK8: 다음앤큐큐 | KL8: 다음앤큐큐 | KM8: 다음앤큐큐 | KN8: 다음앤큐큐 | KO8: 다음앤큐큐 | KP8: 다음앤큐큐 | KQ8: 다음앤큐큐 | KR8: 다음앤큐큐 | KS8: 다음앤큐큐 | KT8: 다음앤큐큐 | KU8: 다음앤큐큐 | KV8: 다음앤큐큐 | KW8: 다음앤큐큐 | KX8: 다음앤큐큐 | KY8: 다음앤큐큐 | KZ8: 다음앤큐큐 | LA8: 다음앤큐큐 | LB8: 다음앤큐큐 | LC8: 다음앤큐큐 | LD8: 다음앤큐큐 | LE8: 다음앤큐큐 | LF8: 다음앤큐큐 | LG8: 다음앤큐큐 | LH8: 다음앤큐큐 | LI8: 다음앤큐큐 | LJ8: 다음앤큐큐 | LK8: 다음앤큐큐 | LL8: 다음앤큐큐 | LM8: 다음앤큐큐 | LN8: 다음앤큐큐 | LO8: 다음앤큐큐 | LP8: 다음앤큐큐 | LQ8: 다음앤큐큐 | LR8: 다음앤큐큐 | LS8: 다음앤큐큐 | LT8: 다음앤큐큐 | LU8: 다음앤큐큐 | LV8: 다음앤큐큐 | LW8: 다음앤큐큐 | LX8: 다음앤큐큐 | LY8: 다음앤큐큐 | LZ8: 다음앤큐큐 | MA8: 다음앤큐큐 | MB8: 다음앤큐큐 | MC8: 다음앤큐큐 | MD8: 다음앤큐큐 | ME8: 다음앤큐큐 | MF8: 다음앤큐큐 | MG8: 다음앤큐큐 | MH8: 다음앤큐큐 | MI8: 다음앤큐큐 | MJ8: 다음앤큐큐 | MK8: 다음앤큐큐 | ML8: 다음앤큐큐 | MM8: 다음앤큐큐 | MN8: 다음앤큐큐 | MO8: 다음앤큐큐 | MP8: 다음앤큐큐 | MQ8: 다음앤큐큐 | MR8: 다음앤큐큐 | MS8: 다음앤큐큐 | MT8: 다음앤큐큐 | MU8: 다음앤큐큐 | MV8: 다음앤큐큐 | MW8: 다음앤큐큐 | MX8: 다음앤큐큐 | MY8: 다음앤큐큐 | MZ8: 다음앤큐큐 | NA8: 다음앤큐큐 | NB8: 다음앤큐큐 | NC8: 다음앤큐큐 | ND8: 다음앤큐큐 | NE8: 다음앤큐큐 | NF8: 다음앤큐큐 | NG8: 다음앤큐큐 | NH8: 다음앤큐큐 | NI8: 다음앤큐큐 | NJ8: 다음앤큐큐 | NK8: 다음앤큐큐 | NL8: 다음앤큐큐 | NM8: 다음앤큐큐 | NN8: 다음앤큐큐 | NO8: 다음앤큐큐 | NP8: 다음앤큐큐 | NQ8: 다음앤큐큐 | NR8: 다음앤큐큐 | NS8: 다음앤큐큐 | NT8: 다음앤큐큐 | NU8: 다음앤큐큐 | NV8: 다음앤큐큐 | NW8: 다음앤큐큐 | NX8: 다음앤큐큐 | PB8: 다음앤큐큐 | PC8: ALLIED | PD8: ALLIED | PE8: ALLIED | PF8: ALLIED | PG8: ALLIED | PH8: ALLIED | PI8: ALLIED | PJ8: ALLIED | PK8: ALLIED | PL8: ALLIED | PM8: ALLIED | PN8: ALLIED | PO8: ALLIED | PP8: ALLIED | PQ8: ALLIED | PR8: ALLIED | PS8: ALLIED | PT8: ALLIED | PU8: ALLIED | PV8: ALLIED | PW8: ALLIED | PX8: ALLIED | PY8: ALLIED | PZ8: ALLIED | QA8: ALLIED | QB8: ALLIED | QC8: ALLIED | QD8: ALLIED | QE8: ALLIED | QF8: ALLIED | QG8: ALLIED | QH8: ALLIED | QI8: ALLIED | QJ8: ALLIED | QK8: ALLIED | QL8: ALLIED | QM8: ALLIED | QN8: ALLIED | QO8: ALLIED | QP8: ALLIED | QQ8: ALLIED | QR8: ALLIED | QS8: ALLIED | QT8: ALLIED | QU8: ALLIED | QV8: ALLIED | QW8: ALLIED | QX8: ALLIED | QY8: ALLIED | QZ8: ALLIED | RA8: ALLIED | RB8: ALLIED | RC8: ALLIED | RD8: ALLIED | RE8: ALLIED | RF8: ALLIED | RG8: ALLIED | RH8: ALLIED | RI8: ALLIED | RJ8: ALLIED | RK8: ALLIED | RL8: ALLIED | RM8: ALLIED | RN8: ALLIED | RO8: ALLIED | RP8: ALLIED | RQ8: ALLIED | RR8: ALLIED | RS8: ALLIED | RT8: ALLIED | RU8: ALLIED | RV8: ALLIED | RW8: ALLIED | RX8: ALLIED | RY8: ALLIED | RZ8: ALLIED | SA8: ALLIED | SB8: ALLIED | SC8: ALLIED | SD8: ALLIED | SE8: ALLIED | SF8: ALLIED | SG8: ALLIED | SH8: ALLIED | SI8: ALLIED | SJ8: ALLIED | SK8: ALLIED | SL8: ALLIED | SM8: ALLIED | SN8: ALLIED | SO8: ALLIED | SP8: ALLIED | SQ8: ALLIED | SR8: ALLIED | SS8: ALLIED | ST8: ALLIED | SU8: ALLIED | SV8: ALLIED | SW8: ALLIED | SX8: ALLIED | SY8: ALLIED | SZ8: ALLIED | TA8: ALLIED | TB8: ALLIED | TC8: ALLIED | TD8: ALLIED | UH8: ALLIED | UI8: 웅가리아 | VB8: 나투어 | VY8: 태평양 | VZ8: 태평양 | WA8: 태평양 | WB8: 태평양 | WC8: 태평양 | WD8: 태평양 | WE8: 태평양 | WF8: 태평양 | WG8: 태평양 | WH8: 태평양 | WI8: 태평양 | WJ8: 태평양 | WK8: 태평양 | WL8: 태평양 | WM8: 태평양 | WN8: 태평양 | WO8: 태평양 | WP8: 태평양 | WQ8: 태평양 | WR8: 태평양 | WS8: 태평양 | WT8: 태평양 | WU8: 태평양 | WV8: 태평양 | WW8: 태평양 | WX8: 태평양 | WY8: 태평양 | WZ8: 태평양 | XA8: 태평양 | XB8: 태평양 | XC8: 태평양 | XD8: 태평양 | XE8: 태평양 | XF8: 태평양 | XG8: 태평양 | XH8: 태평양 | XI8: 태평양 | XJ8: 태평양 | XK8: 태평양 | XL8: 태평양 | XM8: 태평양 | XN8: 태평양 | XO8: 태평양 | XP8: 태평양 | XQ8: 태평양 | XR8: 태평양 | XS8: 태평양 | XT8: 태평양 | XU8: 태평양 | XV8: 태평양 | XW8: 태평양 | XX8: 태평양 | XY8: 태평양 | XZ8: 태평양 | YA8: 태평양 | YB8: 태평양 | YC8: 태평양 | YD8: 태평양 | YE8: 태평양 | YF8: 태평양 | YG8: 태평양 | YH8: 태평양 | YI8: 태평양 | YJ8: 태평양 | YK8: 태평양 | YL8: 태평양 | YM8: 태평양 | YN8: 태평양 | YO8: 태평양 | YP8: 태평양 | YQ8: 태평양 | YR8: 태평양 | YS8: 태평양 | YT8: 태평양 | YU8: 태평양 | YV8: 태평양 | YW8: 태평양 | YX8: 태평양 | YY8: 태평양 | YZ8: 태평양 | ZA8: 태평양 | ZB8: 태평양 | ZC8: 태평양 | ZD8: 태평양 | ZE8: 태평양 | ZF8: 태평양 | ZG8: 태평양 | ZH8: 태평양 | ZI8: 태평양 | ZJ8: 태평양 | ZK8: 태평양 | ZL8: 태평양 | ZM8: 태평양 | ZN8: 태평양 | ZO8: 태평양 | ZP8: 태평양 | ZQ8: 태평양 | ZR8: 태평양 | ZS8: 태평양 | ZT8: 태평양 | ZU8: 태평양 | ZV8: 태평양 | ZW8: 태평양 | ABA8: 태평양 | ABB8: 신주원 | ABC8: 신주원 | ABD8: 신주원 | ABE8: 신주원 | ABF8: 신주원 | ABG8: 신주원 | ABH8: 신주원 | ABI8: 신주원 | ABJ8: 신주원 | ABK8: 신주원 | ABL8: 신주원 | ABM8: 신주원 | ABN8: 신주원 | ABO8: 신주원 | ABP8: 신주원 | ABQ8: 신주원 | ABR8: 신주원 | ABS8: 신주원 | ABT8: 신주원 | ABU8: 신주원 | ABV8: 신주원 | ABW8: 신주원 | ABX8: 신주원 | ABY8: 신주원 | ABZ8: 신주원 | ACA8: 신주원 | ACB8: 신주원 | ACC8: 신주원 | ACD8: 신주원 | ACE8: 신주원 | ACF8: 신주원 | ACG8: 신주원 | ACH8: 신주원 | ACI8: 신주원 | ACJ8: 신주원 | ACK8: 신주원 | ACL8: 신주원 | ACM8: 신주원 | ACN8: 신주원 | ACO8: 신주원 | ACP8: 신주원 | ACQ8: 신주원 | ACR8: 신주원 | ACS8: 신주원 | ACT8: 신주원 | ACU8: 신주원 | ACV8: 신주원 | ACW8: 신주원 | ACX8: 신주원 | ACY8: 신주원 | ACZ8: 신주원 | ADA8: 신주원 | ADB8: 신주원 | ADC8: 신주원 | ADD8: 신주원 | ADE8: 신주원 | ADF8: 신주원 | ADG8: 신주원 | ADH8: 신주원 | ADI8: 신주원 | ADJ8: 신주원 | ADK8: 신주원 | ADL8: 신주원 | ADM8: 신주원 | ADN8: 신주원 | ADO8: 신주원 | ADP8: 신주원 | ADQ8: 신주원 | ADR8: 신주원 | ADS8: 신주원 | ADT8: 신주원 | ADU8: 신주원 | ADV8: 신주원 | ADW8: 신주원 | ADX8: 신주원 | ADY8: 신주원 | ADZ8: 신주원 | AEA8: 신주원 | AEB8: 신주원 | AEC8: 신주원 | AED8: 신주원 | AEE8: 신주원 | AEF8: 신주원 | AEG8: 신주원 | AEH8: 신주원 | AEI8: 신주원 | AEJ8: 신주원 | AEK8: 신주원 | AEL8: 신주원 | AEM8: 신주원 | AEN8: 신주원 | AEO8: 신주원 | AEP8: 신주원 | AEQ8: 신주원 | AER8: 남부다운 | AES8: 남부다운 | AET8: 남부다운 | AEU8: 남부다운 | AEV8: 남부다운 | AEW8: 남부다운 | AEX8: 남부다운 | AEY8: 남부다운 | AEZ8: 남부다운 | AFA8: 남부다운 | AFB8: 남부다운 | AFC8: 남부다운 | AFD8: 남부다운 | AFE8: 남부다운 | AFF8: 남부다운 | AFG8: 남부다운 | AFH8: 남부다운 | AFI8: 남부다운 | AFJ8: 남부다운 | AFK8: 남부다운 | AFL8: 남부다운 | AFM8: 남부다운 | AFN8: 남부다운 | AFO8: 남부다운 | AFP8: 남부다운 | AFQ8: 신주원 | AGC8: 신주원 | AGD8: 신주원 | AGE8: 신주원 | AGF8: 신주원 | AGG8: 신주원 | AGH8: 신주원 | AGI8: 신주원 | AGJ8: 신주원 | AGK8: 신주원 | AGL8: 신주원 | AGM8: 신주원 | AGN8: 신주원 | AGO8: 신주원 | AGP8: 신주원 | AGQ8: 신주원 | AGR8: 신주원 | AGS8: 신주원 | AGT8: 신주원 | AGU8: 신주원 | AGV8: 신주원 | AGW8: 신주원 | AGX8: 신주원 | AGY8: 신주원 | AGZ8: 신주원 | AHA8: 신주원 | AHB8: 신주원 | AHC8: 신주원 | AHD8: 남부다운 | AJT8: 구스헤리티지 | AKF8: 23/1/18 평균시세 | AKG8: 23/2/9 평균시세 | AKI8: 12/9 평균시세 | AKJ8: 12/27 평균시세 | AKK8: 1/3 평균시세 | AKL8: 1/27 평균시세 | AKM8: 7/19 평균시세 | AKN8: 8/10 평균시세 | AKO8: 22/12/15 평균시세 | AKP8: 신성통상 | AKQ8: 데상트 | AKR8: 밀레 | AKS8: 르까프 | AKT8: FILA | AKU8: 콜롬비아 글로벌 | AKV8: 나이키 글로벌 | AKW8: 아디다스 글로벌 | AKX8: 내셔널 지오그래픽 | AKY8: 블랙야크 | AKZ8: NFL | ALA8: 코오롱 | ALB8: NEPA | ALC8: 푸마 | ALD8: 디스커버리 | ALE8: 평균 | ALF8: 평균 | ALU8: LY인터내셔널 | ALV8: LY인터내셔널 | ALW8: LY인터내셔널 | ALX8: LY인터내셔널 | ALY8: LY인터내셔널 | ALZ8: LY인터내셔널 | AMA8: LY인터내셔널 | AMB8: LY인터내셔널 | AMC8: LY인터내셔널 | AMD8: LY인터내셔널 | AME8: LY인터내셔널 | AMF8: LY인터내셔널 | AMG8: LY인터내셔널 | AMH8: LY인터내셔널 | AMI8: LY인터내셔널 | AMJ8: LY인터내셔널 | AMK8: GQ다운
